<?xml version="1.0" encoding="utf-8"?>
<!--
This URDF was automatically created by SolidWorks to URDF Exporter! Originally created by Stephen Brawner (brawner@gmail.com)
Commit Version: 1.6.0-4-g7f85cfe  Build Version: 1.6.7995.38578
For more information, please see http://wiki.ros.org/sw_urdf_exporter
-->
<robot name="pai_10dof_v3_0311">
<mujoco>
  <compiler 
    meshdir="package://legged_hunter_description/meshes/" 
    balanceinertia="true" 
    discardvisual="false" />
</mujoco>

  <gazebo>
    <plugin name="gazebo_ros_control" filename="libhunter_bipedal_hw_sim.so">
      <robotNamespace>/</robotNamespace>
      <robotParam>legged_robot_description</robotParam>
      <robotSimType>legged_gazebo/LeggedHWSim</robotSimType>
    </plugin>
  </gazebo>

  <gazebo>
    <plugin filename="libgazebo_ros_p3d.so" name="p3d_base_controller">
      <alwaysOn>true</alwaysOn>
      <updateRate>500.0</updateRate>
      <bodyName>base_link</bodyName>
      <topicName>ground_truth/state</topicName>
      <gaussianNoise>0</gaussianNoise>
      <frameName>world</frameName>
      <xyzOffsets>0 0 0</xyzOffsets>
      <rpyOffsets>0 0 0</rpyOffsets>
    </plugin>
  </gazebo>

	<link name="base_link">
		<inertial>
			<origin xyz="0.0083901 -0.0011217 0.0571961" rpy="0 0 0" />
			<mass value="1.6042619" />
			<inertia ixx="0.0044403" ixy="0.0001368" ixz="0.0002994" iyy="0.0044715" iyz="-3.65E-05" izz="0.0042503" />
		</inertial>
		<visual>
			<origin xyz="0 0 0" rpy="0 0 0" />
			<geometry>
				<mesh filename="package://legged_hunter_description/meshes/base_link.STL" />
			</geometry>
			<material name="">
				<color rgba="1 1 1 1" />
			</material>
		</visual>
		<collision>
			<!-- <origin xyz="0 0 0" rpy="0 0 0" />
			<geometry>
				<mesh filename="package://legged_hunter_description/meshes/base_link.STL" />
			</geometry> -->
			<origin rpy="0 0 0" xyz="0 0 0.045" />
			<geometry>
				<box size="0.1 0.1 0.09" />
			</geometry>
		</collision>
	</link>
	
	<!-- Imu is fixed to the base link -->
    <joint name="imu_joint" type="fixed">
      <origin rpy="0. 0. 0." xyz="0. 0. 0"/>
      <parent link="base_link"/>
      <child link="imu_link"/>
    </joint>
    <!-- Imu link -->
    <link name="imu_link">
      <inertial>
        <mass value="0.01"/>
        <origin rpy="0 0 0" xyz="0 0 0"/>
        <inertia ixx="0.000001" ixy="0" ixz="0" iyy="0.000001" iyz="0" izz="0.000001"/>
      </inertial>
      <visual>
        <origin rpy="0 0 0" xyz="0 0 0"/>
        <geometry>
          <box size="0.015 0.015 0.004"/>
        </geometry>
      </visual>
      <material name="orange">
        <color rgba="255 108 10 255"/>
      </material>
    </link>
    <gazebo reference="imu_joint">
      <disableFixedJointLumping>true</disableFixedJointLumping>
    </gazebo>

  <!-- ************************************************************ -->
  <!-- ************************ Left Leg ************************** -->
  <!-- ************************************************************ -->

  <!-- ************* part 2 *************** -->
	<joint name="leg_l2_joint" type="revolute">
		<origin xyz="0 0.075 0" rpy="0 0 0" />
		<parent link="base_link" />
		<child link="leg_l2_link" />
		<axis xyz="0 0 1" />
		<limit lower="-3.14" upper="3.14" effort="21" velocity="21" />
	</joint>
	<link name="leg_l2_link">
		<inertial>
			<origin xyz="-0.0222049 0 -0.0213255" rpy="0 0 0" />
			<mass value="0.34" />
			<inertia ixx="4.37E-05" ixy="0" ixz="-2.14E-05" iyy="5.97E-05" iyz="0" izz="3.12E-05" />
		</inertial>
		<visual>
			<origin xyz="0 0 0" rpy="0 0 0" />
			<geometry>
				<mesh filename="package://legged_hunter_description/meshes/l_hip_yaw_link.STL" />
			</geometry>
			<material name="">
				<color rgba="1 1 1 1" />
			</material>
		</visual>
		<collision>
			<!-- <origin xyz="0 0 0" rpy="0 0 0" />
			<geometry>
				<mesh filename="package://legged_hunter_description/meshes/l_hip_yaw_link.STL" />
			</geometry> -->
			<origin xyz="0 0 0" rpy="0 0 0" />
			<geometry>
				<box size="0.0001 0.0001 0.0001" />
			</geometry>
		</collision>
	</link>



	<!-- ************* part 1 *************** -->
	<joint name="leg_l1_joint" type="revolute">
		<origin xyz="-0.037 0 -0.054" rpy="0 0 0" />
		<parent link="leg_l2_link" />
		<child link="leg_l1_link" />
		<axis xyz="1 0 0" />
		<limit lower="-3.14" upper="3.14" effort="21" velocity="21" />
	</joint>
	<link name="leg_l1_link">
		<inertial>
			<origin xyz="0.018445 0 -0.0030972" rpy="0 0 0" />
			<mass value="0.367" />
			<inertia ixx="4.04E-05" ixy="0" ixz="-1.5E-06" iyy="4.96E-05" iyz="0" izz="5.32E-05" />
		</inertial>
		<visual>
			<origin xyz="0 0 0" rpy="0 0 0" />
			<geometry>
				<mesh filename="package://legged_hunter_description/meshes/l_hip_roll_link.STL" />
			</geometry>
			<material name="">
				<color rgba="1 1 1 1" />
			</material>
		</visual>
		<collision>
			<!-- <origin xyz="0 0 0" rpy="0 0 0" />
			<geometry>
				<mesh filename="package://legged_hunter_description/meshes/l_hip_roll_link.STL" />
			</geometry> -->
			<origin rpy="0 0 0" xyz="0 0 0" />
			<geometry>
				<box size="0.0001 0.0001 0.0001" />
			</geometry>
		</collision>
	</link>


	<!-- ************* part 3 *************** -->
	<joint name="leg_l3_joint" type="revolute">
		<origin xyz="0.039 0 0" rpy="0 0 0" />
		<parent link="leg_l1_link" />
		<child link="leg_l3_link" />
		<axis xyz="0 -1 0" />
		<limit lower="-3.14" upper="3.14" effort="21" velocity="21" />
	</joint>
	<link name="leg_l3_link">
		<inertial>
			<origin xyz="0 0.0008496 -0.0657852" rpy="0 0 0" />
			<mass value="0.476" />
			<inertia ixx="0.0003309" ixy="0" ixz="0" iyy="0.0003287" iyz="-7.3E-06" izz="3.47E-05" />
		</inertial>
		<visual>
			<origin xyz="0 0 0" rpy="0 0 0" />
			<geometry>
				<mesh filename="package://legged_hunter_description/meshes/l_thigh_link.STL" />
			</geometry>
			<material name="">
				<color rgba="1 1 1 1" />
			</material>
		</visual>
		<collision>
			<!-- <origin xyz="0 0 0" rpy="0 0 0" />
			<geometry>
				<mesh filename="package://legged_hunter_description/meshes/l_thigh_link.STL" />
			</geometry> -->
			<origin xyz="0.00 0 -0.05" rpy="0 0 0" />
            <geometry>
                <box size="0.01 0.01 0.09" />
            </geometry>
		</collision>
	</link>


	<!-- ************* part 4 *************** -->
	<joint name="leg_l4_joint" type="revolute">
		<origin xyz="0 0 -0.15" rpy="0 0 0" />
		<parent link="leg_l3_link" />
		<child link="leg_l4_link" />
		<axis xyz="0 1 0" />
		<limit lower="-3.14" upper="3.14" effort="21" velocity="21" />
	</joint>
	<link name="leg_l4_link">
		<inertial>
			<origin xyz="-0.0045962 0.012568 -0.063722" rpy="0 0 0" />
			<mass value="0.361" />
			<inertia ixx="0.0004571" ixy="1.33E-05" ixz="5.7E-06" iyy="0.0004253" iyz="1.57E-05" izz="0.0001177" />
		</inertial>
		<visual>
			<origin xyz="0 0 0" rpy="0 0 0" />
			<geometry>
				<mesh filename="package://legged_hunter_description/meshes/l_calf_link.STL" />
			</geometry>
			<material name="">
				<color rgba="1 1 1 1" />
			</material>
		</visual>
		<collision>
			<!-- <origin xyz="0 0 0" rpy="0 0 0" />
			<geometry>
				<mesh filename="package://legged_hunter_description/meshes/l_calf_link.STL" />
			</geometry> -->
			<origin xyz="0.0 0.0 -0.05" rpy="0 0 0" />
			<geometry>
				<box size="0.01 0.01 0.09" />
			</geometry>
		</collision>
	</link>


	<!-- ************* part 5 *************** -->
	<joint name="leg_l5_joint" type="revolute">
		<origin xyz="0 0 -0.16" rpy="0 0 0" />
		<parent link="leg_l4_link" />
		<child link="leg_l5_link" />
		<axis xyz="0 -1 0" />
		<limit lower="-3.14" upper="3.14" effort="21" velocity="21" />
	</joint>
	<link name="leg_l5_link">
		<inertial>
			<origin xyz="0.0013494 0 -0.0128062" rpy="0 0 0" />
			<mass value="0.089" />
			<inertia ixx="4.3E-06" ixy="0" ixz="1.9E-06" iyy="4.33E-05" iyz="0" izz="4.18E-05" />
		</inertial>
		<visual>
			<!-- <origin xyz="0 0 0" rpy="0 0 0" />
			<geometry>
				<mesh filename="package://legged_hunter_description/meshes/l_toe_link.STL" />
			</geometry> -->
			<origin xyz="0.012 0.0 0.0" rpy="0 0 0" />
            <geometry>
                <box size="0.1 0.04 0.01" />
			</geometry>
			<material name="">
				<color rgba="1 1 1 1" />
			</material>
		</visual>
		<collision>
			<!-- <origin xyz="0 0 0" rpy="0 0 0" />
			<geometry>
				<mesh filename="package://legged_hunter_description/meshes/l_toe_link.STL" />
			</geometry> -->
			<origin xyz="0.012 0.0 0.0" rpy="0 0 0" />
            <geometry>
                <box size="0.1 0.04 0.01" />
            </geometry>
		</collision>
	</link>
  <joint name="leg_l5_fixed_1" type="fixed">
    <origin xyz="0.06 0 -0.007" rpy="0 0 0" />
    <parent link="leg_l5_link" />
    <child link="leg_l_f1_link" />
  </joint>
  <link name="leg_l_f1_link">
    <inertial>
      <mass value="0.01" />
      <inertia ixx="0.000001" ixy="0" ixz="0" iyy="0.000001" iyz="0" izz="0.000001" />
    </inertial>
    <visual>
      <origin rpy="0 0 0" xyz="0 0 0"/>
      <geometry>
        <sphere radius="0.001"/>
      </geometry>
    </visual>
    <collision>
      <origin rpy="0 0 0" xyz="0 0 0"/>
      <geometry>
        <sphere radius="0.001"/>
      </geometry>
    </collision>
  </link>

  <joint name="leg_l5_fixed_2" type="fixed">
    <origin xyz="-0.030 0 -0.007" rpy="0 0 0" />
    <parent link="leg_l5_link" />
    <child link="leg_l_f2_link" />
  </joint>
  <link name="leg_l_f2_link">
    <inertial>
      <mass value="0.01" />
      <inertia ixx="0.000001" ixy="0" ixz="0" iyy="0.000001" iyz="0" izz="0.000001" />
    </inertial>
    <visual>
      <origin rpy="0 0 0" xyz="0 0 0"/>
      <geometry>
        <sphere radius="0.001"/>
      </geometry>
    </visual>
    <collision>
      <origin rpy="0 0 0" xyz="-0 0 0"/>
      <geometry>
        <sphere radius="0.001"/>
      </geometry>
    </collision>
  </link>

  <gazebo reference="leg_l1_link">
    <mu1>0.6</mu1>
    <mu2>0.6</mu2>
    <self_collide>1</self_collide>
  </gazebo>
  <gazebo reference="leg_l2_link">
    <mu1>0.6</mu1>
    <mu2>0.6</mu2>
    <self_collide>1</self_collide>
  </gazebo>
  <gazebo reference="leg_l3_link">
    <mu1>0.6</mu1>
    <mu2>0.6</mu2>
    <self_collide>1</self_collide>
  </gazebo>
  <gazebo reference="leg_l4_link">
    <mu1>0.6</mu1>
    <mu2>0.6</mu2>
    <self_collide>1</self_collide>
  </gazebo>
  <gazebo reference="leg_l5_link">
    <mu1>1.5</mu1>
    <mu2>1.5</mu2>
    <self_collide>1</self_collide>
    <kp value="1000000.0"/>
    <kd value="100.0"/>
    <maxVel>1.0</maxVel>
    <minDepth>0.00</minDepth>
  </gazebo>
  <gazebo reference="leg_l_f1_link">
    <mu1>1.5</mu1>
    <mu2>1.5</mu2>
    <self_collide>1</self_collide>
    <kp value="1000000.0"/>
    <kd value="100.0"/>
    <maxVel>1.0</maxVel>
    <minDepth>0.00</minDepth>
  </gazebo>
  <gazebo reference="leg_l_f2_link">
    <mu1>1.5</mu1>
    <mu2>1.5</mu2>
    <self_collide>1</self_collide>
    <kp value="1000000.0"/>
    <kd value="100.0"/>
    <maxVel>1.0</maxVel>
    <minDepth>0.00</minDepth>
  </gazebo>

  <transmission name="leg_l1_tran">
    <type>transmission_interface/SimpleTransmission</type>
    <joint name="leg_l1_joint">
      <hardwareInterface>hardware_interface/EffortJointInterface</hardwareInterface>
    </joint>
    <actuator name="leg_l1_motor">
      <hardwareInterface>hardware_interface/EffortJointInterface</hardwareInterface>
      <mechanicalReduction>1</mechanicalReduction>
    <maxVelocity>1.484</maxVelocity><!-- 85rpm -->
	  <maxEffort>36.0</maxEffort><!-- 36Nm -->
    </actuator>
  </transmission>

  <transmission name="leg_l2_tran">
    <type>transmission_interface/SimpleTransmission</type>
    <joint name="leg_l2_joint">
      <hardwareInterface>hardware_interface/EffortJointInterface</hardwareInterface>
    </joint>
    <actuator name="leg_l2_motor">
      <hardwareInterface>hardware_interface/EffortJointInterface</hardwareInterface>
      <mechanicalReduction>1</mechanicalReduction>
    <maxVelocity>2.6545</maxVelocity><!-- 160rpm -->
	  <maxEffort>94.0</maxEffort><!-- 94Nm -->
    </actuator>
  </transmission>

  <transmission name="leg_l3_tran">
    <type>transmission_interface/SimpleTransmission</type>
    <joint name="leg_l3_joint">
      <hardwareInterface>hardware_interface/EffortJointInterface</hardwareInterface>
    </joint>
    <actuator name="leg_l3_motor">
      <hardwareInterface>hardware_interface/EffortJointInterface</hardwareInterface>
      <mechanicalReduction>1</mechanicalReduction>
    <maxVelocity>2.6545</maxVelocity><!-- 160rpm -->
	  <maxEffort>94.0</maxEffort><!-- 94Nm -->
    </actuator>
  </transmission>

  <transmission name="leg_l4_tran">
    <type>transmission_interface/SimpleTransmission</type>
    <joint name="leg_l4_joint">
      <hardwareInterface>hardware_interface/EffortJointInterface</hardwareInterface>
    </joint>
    <actuator name="leg_l4_motor">
      <hardwareInterface>hardware_interface/EffortJointInterface</hardwareInterface>
      <mechanicalReduction>1</mechanicalReduction>
    <maxVelocity>1.484</maxVelocity><!-- 85rpm -->
	<maxEffort>36.0</maxEffort><!-- 36Nm -->
    </actuator>
  </transmission>

  <transmission name="leg_l5_tran">
    <type>transmission_interface/SimpleTransmission</type>
    <joint name="leg_l5_joint">
      <hardwareInterface>hardware_interface/EffortJointInterface</hardwareInterface>
    </joint>
    <actuator name="leg_l5_motor">
      <hardwareInterface>hardware_interface/EffortJointInterface</hardwareInterface>
      <mechanicalReduction>1</mechanicalReduction>
    </actuator>
  </transmission>
  <!-- ************************************************************ -->
  <!-- ************************ Right Leg ************************** -->
  <!-- ************************************************************ -->
	
  <!-- ************* part 2 *************** -->
	<joint name="leg_r2_joint" type="revolute">
		<origin xyz="0 -0.075 0" rpy="0 0 0" />
		<parent link="base_link" />
		<child link="leg_r2_link" />
		<axis xyz="0 0 1" />
		<limit lower="-3.14" upper="3.14" effort="21" velocity="21" />
	</joint>
	<link name="leg_r2_link">
		<inertial>
			<origin xyz="-0.0222049 0 -0.0213255" rpy="0 0 0" />
			<mass value="0.34" />
			<inertia ixx="4.37E-05" ixy="0" ixz="-2.14E-05" iyy="5.97E-05" iyz="0" izz="3.12E-05" />
		</inertial>
		<visual>
			<origin xyz="0 0 0" rpy="0 0 0" />
			<geometry>
				<mesh filename="package://legged_hunter_description/meshes/r_hip_yaw_link.STL" />
			</geometry>
			<material name="">
				<color rgba="1 1 1 1" />
			</material>
		</visual>
		<collision>
			<!-- <origin xyz="0 0 0" rpy="0 0 0" />
			<geometry>
				<mesh filename="package://legged_hunter_description/meshes/r_hip_yaw_link.STL" />
			</geometry> -->
			<origin xyz="0 0 0" rpy="0 0 0" />
			<geometry>
				<box size="0.0001 0.0001 0.0001" />
			</geometry>
		</collision>
	</link>

  <!-- ************* part 1 *************** -->
	<joint name="leg_r1_joint" type="revolute">
		<origin xyz="-0.037 0 -0.054" rpy="0 0 0" />
		<parent link="leg_r2_link" />
		<child link="leg_r1_link" />
		<axis xyz="1 0 0" />
		<limit lower="-3.14" upper="3.14" effort="21" velocity="21" />
	</joint>
	<link name="leg_r1_link">
		<inertial>
			<origin xyz="0.018445 0 -0.0030972" rpy="0 0 0" />
			<mass value="0.367" />
			<inertia ixx="4.04E-05" ixy="0" ixz="-1.5E-06" iyy="4.96E-05" iyz="0" izz="5.32E-05" />
		</inertial>
		<visual>
			<origin xyz="0 0 0" rpy="0 0 0" />
			<geometry>
				<mesh filename="package://legged_hunter_description/meshes/r_hip_roll_link.STL" />
			</geometry>
			<material name="">
				<color rgba="1 1 1 1" />
			</material>
		</visual>
		<collision>
			<!-- <origin xyz="0 0 0" rpy="0 0 0" />
			<geometry>
				<mesh filename="package://legged_hunter_description/meshes/r_hip_roll_link.STL" />
			</geometry> -->
			<origin xyz="0 0 0" rpy="0 0 0" />
			<geometry>
				<box size="0.0001 0.0001 0.0001" />
			</geometry>
		</collision>
	</link>

  <!-- ************* part 3 *************** -->
	<joint name="leg_r3_joint" type="revolute">
		<origin xyz="0.039 0 0" rpy="0 0 0" />
		<parent link="leg_r1_link" />
		<child link="leg_r3_link" />
		<axis xyz="0 1 0" />
		<limit lower="-3.14" upper="3.14" effort="21" velocity="21" />
	</joint>
	<link name="leg_r3_link">
		<inertial>
			<origin xyz="0 -0.0008496 -0.0657852" rpy="0 0 0" />
			<mass value="0.476" />
			<inertia ixx="0.0003309" ixy="0" ixz="0" iyy="0.0003287" iyz="-7.3E-06" izz="3.47E-05" />
		</inertial>
		<visual>
			<origin xyz="0 0 0" rpy="0 0 0" />
			<geometry>
				<mesh filename="package://legged_hunter_description/meshes/r_thigh_link.STL" />
			</geometry>
			<material name="">
				<color rgba="1 1 1 1" />
			</material>
		</visual>
		<collision>
			<!-- <origin xyz="0 0 0" rpy="0 0 0" />
			<geometry>
				<mesh filename="package://legged_hunter_description/meshes/r_thigh_link.STL" />
			</geometry> -->
			<origin xyz="0.0 0 -0.05" rpy="0 0 0" />
			<geometry>
				<box size="0.01 0.01 0.09" />
			</geometry>
		</collision>
	</link>

  <!-- ************* part 4 *************** -->
	<joint name="leg_r4_joint" type="revolute">
		<origin xyz="0 0 -0.15" rpy="0 0 0" />
		<parent link="leg_r3_link" />
		<child link="leg_r4_link" />
		<axis xyz="0 1 0" />
		<limit lower="-3.14" upper="3.14" effort="21" velocity="21" />
	</joint>
	<link name="leg_r4_link">
		<inertial>
			<origin xyz="-0.0045962 -0.0125678 -0.0637218" rpy="0 0 0" />
			<mass value="0.361" />
			<inertia ixx="0.0004571" ixy="-1.33E-05" ixz="5.7E-06" iyy="0.0004253" iyz="1.57E-05" izz="0.0001177" />
		</inertial>
		<visual>
			<origin xyz="0 0 0" rpy="0 0 0" />
			<geometry>
				<mesh filename="package://legged_hunter_description/meshes/r_calf_link.STL" />
			</geometry>
			<material name="">
				<color rgba="1 1 1 1" />
			</material>
		</visual>
		<collision>
			<!-- <origin xyz="0 0 0" rpy="0 0 0" />
			<geometry>
				<mesh filename="package://legged_hunter_description/meshes/r_calf_link.STL" />
			</geometry> -->
			<origin xyz="0.00 0.0 -0.05" rpy="0 0 0" />
			<geometry>
				<box size="0.01 0.01 0.09" />
			</geometry>
		</collision>
	</link>

  <!-- ************* part 5 *************** -->
	<joint name="leg_r5_joint" type="revolute">
		<origin xyz="0 0 -0.16" rpy="0 0 0" />
		<parent link="leg_r4_link" />
		<child link="leg_r5_link" />
		<axis xyz="0 1 0" />
		<limit lower="-3.14" upper="3.14" effort="21" velocity="21" />
	</joint>
	<link name="leg_r5_link">
		<inertial>
			<origin xyz="0.0013494 0 -0.0128062" rpy="0 0 0" />
			<mass value="0.089" />
			<inertia ixx="4.3E-06" ixy="0" ixz="1.9E-06" iyy="4.33E-05" iyz="0" izz="4.18E-05" />
		</inertial>
		<visual>
			<!-- <origin xyz="0 0 0" rpy="0 0 0" />
			<geometry>
				<mesh filename="package://legged_hunter_description/meshes/r_toe_link.STL" />
			</geometry> -->
			<origin xyz="0.012 0.0 0.0" rpy="0 0 0" />
			<geometry>
				<box size="0.1 0.04 0.01" />
			</geometry>
			<material name="">
				<color rgba="1 1 1 1" />
			</material>
		</visual>
		<collision>
			<!-- <origin xyz="0 0 0" rpy="0 0 0" />
			<geometry>
				<mesh filename="package://legged_hunter_description/meshes/r_toe_link.STL" />
			</geometry> -->
			<origin xyz="0.012 0.0 0.0" rpy="0 0 0" />
			<geometry>
				<box size="0.1 0.04 0.01" />
			</geometry>
		</collision>
	</link>
<joint name="leg_r5_fixed_1" type="fixed">
    <origin xyz="0.06 0 -0.007" rpy="0 0 0" />
    <parent link="leg_r5_link" />
    <child link="leg_r_f1_link" />
  </joint>
  <link name="leg_r_f1_link">
    <inertial>
      <mass value="0.01" />
      <inertia ixx="0.000001" ixy="0" ixz="0" iyy="0.000001" iyz="0" izz="0.000001" />
    </inertial>
    <visual>
      <origin rpy="0 0 0" xyz="0 0 0"/>
      <geometry>
        <sphere radius="0.001"/>
      </geometry>
    </visual>
    <collision>
      <origin rpy="0 0 0" xyz="0 0 0"/>
      <geometry>
        <sphere radius="0.001"/>
      </geometry>
    </collision>
  </link>

  <joint name="leg_r5_fixed_2" type="fixed">
    <origin xyz="-0.030 0 -0.007" rpy="0 0 0" />
    <parent link="leg_r5_link" />
    <child link="leg_r_f2_link" />
  </joint>
  <link name="leg_r_f2_link">
    <inertial>
      <mass value="0.01" />
      <inertia ixx="0.000001" ixy="0" ixz="0" iyy="0.000001" iyz="0" izz="0.000001" />
    </inertial>
    <visual>
      <origin rpy="0 0 0" xyz="0 0 0"/>
      <geometry>
        <sphere radius="0.001"/>
      </geometry>
    </visual>
    <collision>
      <origin rpy="0 0 0" xyz="0 0 0"/>
      <geometry>
        <sphere radius="0.001"/>
      </geometry>
    </collision>
  </link>

  <gazebo reference="leg_r1_link">
    <mu1>0.6</mu1>
    <mu2>0.6</mu2>
    <self_collide>1</self_collide>
  </gazebo>
  <gazebo reference="leg_r2_link">
    <mu1>0.6</mu1>
    <mu2>0.6</mu2>
    <self_collide>1</self_collide>
  </gazebo>
  <gazebo reference="leg_r3_link">
    <mu1>0.6</mu1>
    <mu2>0.6</mu2>
    <self_collide>1</self_collide>
  </gazebo>
  <gazebo reference="leg_r4_link">
    <mu1>0.6</mu1>
    <mu2>0.6</mu2>
    <self_collide>1</self_collide>
  </gazebo>
  <gazebo reference="leg_r5_link">
    <mu1>1.5</mu1>
    <mu2>1.5</mu2>
    <self_collide>1</self_collide>
    <kp value="1000000.0"/>
    <kd value="100.0"/>
    <maxVel>1.0</maxVel>
    <minDepth>0.00</minDepth>
  </gazebo>
  <gazebo reference="leg_r_f1_link">
    <mu1>1.5</mu1>
    <mu2>1.5</mu2>
    <self_collide>1</self_collide>
    <kp value="1000000.0"/>
    <kd value="100.0"/>
    <maxVel>1.0</maxVel>
    <minDepth>0.00</minDepth>
  </gazebo>
  <gazebo reference="leg_r_f2_link">
    <mu1>1.5</mu1>
    <mu2>1.5</mu2>
    <self_collide>1</self_collide>
    <kp value="1000000.0"/>
    <kd value="100.0"/>
    <maxVel>1.0</maxVel>
    <minDepth>0.00</minDepth>
  </gazebo>

  <transmission name="leg_r1_tran">
    <type>transmission_interface/SimpleTransmission</type>
    <joint name="leg_r1_joint">
      <hardwareInterface>hardware_interface/EffortJointInterface</hardwareInterface>
    </joint>
    <actuator name="leg_r1_motor">
      <hardwareInterface>hardware_interface/EffortJointInterface</hardwareInterface>
      <mechanicalReduction>1</mechanicalReduction>
      	  <maxVelocity>1.484</maxVelocity><!-- 85rpm -->
	<maxEffort>36.0</maxEffort><!-- 36Nm -->
    </actuator>
  </transmission>

  <transmission name="leg_r2_tran">
    <type>transmission_interface/SimpleTransmission</type>
    <joint name="leg_r2_joint">
      <hardwareInterface>hardware_interface/EffortJointInterface</hardwareInterface>
    </joint>
    <actuator name="leg_r2_motor">
      <hardwareInterface>hardware_interface/EffortJointInterface</hardwareInterface>
      <mechanicalReduction>1</mechanicalReduction>
      	  <maxVelocity>2.6545</maxVelocity><!-- 160rpm -->
	  <maxEffort>94.0</maxEffort><!-- 94Nm -->
    </actuator>
  </transmission>

  <transmission name="leg_r3_tran">
    <type>transmission_interface/SimpleTransmission</type>
    <joint name="leg_r3_joint">
      <hardwareInterface>hardware_interface/EffortJointInterface</hardwareInterface>
    </joint>
    <actuator name="leg_r3_motor">
      <hardwareInterface>hardware_interface/EffortJointInterface</hardwareInterface>
      <mechanicalReduction>1</mechanicalReduction>
      	  <maxVelocity>2.6545</maxVelocity><!-- 160rpm -->
	  <maxEffort>94.0</maxEffort><!-- 94Nm -->
    </actuator>
  </transmission>

  <transmission name="leg_r4_tran">
    <type>transmission_interface/SimpleTransmission</type>
    <joint name="leg_r4_joint">
      <hardwareInterface>hardware_interface/EffortJointInterface</hardwareInterface>
    </joint>
    <actuator name="leg_r4_motor">
      <hardwareInterface>hardware_interface/EffortJointInterface</hardwareInterface>
      <mechanicalReduction>1</mechanicalReduction>
      	  <maxVelocity>1.484</maxVelocity><!-- 85rpm -->
	<maxEffort>36.0</maxEffort><!-- 36Nm -->
    </actuator>
  </transmission>

  <transmission name="leg_r5_tran">
    <type>transmission_interface/SimpleTransmission</type>
    <joint name="leg_r5_joint">
      <hardwareInterface>hardware_interface/EffortJointInterface</hardwareInterface>
    </joint>
    <actuator name="leg_r5_motor">
      <hardwareInterface>hardware_interface/EffortJointInterface</hardwareInterface>
      <mechanicalReduction>1</mechanicalReduction>
    </actuator>
  </transmission>
</robot>