<?xml version="1.0" encoding="utf-8"?>
<!--
This URDF was automatically created by SolidWorks to URDF Exporter! Originally created by Stephen Brawner (brawner@gmail.com)
Commit Version: 1.6.0-4-g7f85cfe  Build Version: 1.6.7995.38578
For more information, please see http://wiki.ros.org/sw_urdf_exporter
-->
<robot name="hunter">
	<mujoco>
    <compiler 
    meshdir="../meshes_pi/" 
    balanceinertia="true" 
    discardvisual="false" />
    </mujoco>


	<gazebo>
    <plugin name="gazebo_ros_control" filename="libhunter_bipedal_hw_sim.so">
      <robotNamespace>/</robotNamespace>
      <robotParam>legged_robot_description</robotParam>
      <robotSimType>legged_gazebo/LeggedHWSim</robotSimType>
    </plugin>
  	</gazebo>

  	<gazebo>
    <plugin filename="libgazebo_ros_p3d.so" name="p3d_base_controller">
      <alwaysOn>true</alwaysOn>
      <updateRate>500.0</updateRate>
      <bodyName>base_link</bodyName>
      <topicName>ground_truth/state</topicName>
      <gaussianNoise>0</gaussianNoise>
      <frameName>world</frameName>
      <xyzOffsets>0 0 0</xyzOffsets>
      <rpyOffsets>0 0 0</rpyOffsets>
    </plugin>
  	</gazebo>

	<link name="base_link">
		<inertial>
			<origin xyz="0.0019276 -4.6272E-05 0.062874" rpy="0 0 0" />
			<mass value="1.6042619" />
			<inertia ixx="0.0096904" ixy="-0.0001519" ixz="0.0004705" iyy="0.0098326" iyz="-0.0000665" izz="0.0043652" />
		</inertial>
		<visual>
			<origin xyz="0 0 0" rpy="0 0 0" />
			<geometry>
				<mesh filename="package://legged_hunter_description/meshes_pi/base_link.STL" />
			</geometry>
			<material name="">
				<color rgba="1 1 1 1" />
			</material>
		</visual>
		<collision>
			<!-- <origin xyz="0 0 0" rpy="0 0 0" />
			<geometry>
				<mesh filename="package://legged_hunter_description/meshes_pi/base_link.STL" />
			</geometry> -->
			<origin rpy="0 0 0" xyz="0 0 0.045" />
			<geometry>
				<box size="0.1 0.1 0.09" />
			</geometry>
		</collision>
	</link>

	  <joint name="imu_joint" type="fixed">
    <origin rpy="0. 0. 0." xyz="0. 0. 0"/>
    <parent link="base_link"/>
    <child link="imu_link"/>
  </joint>
  <!-- Imu link -->
  <link name="imu_link">
    <inertial>
      <mass value="0.01"/>
      <origin rpy="0 0 0" xyz="0 0 0"/>
      <inertia ixx="0.000001" ixy="0" ixz="0" iyy="0.000001" iyz="0" izz="0.000001"/>
    </inertial>
    <visual>
      <origin rpy="0 0 0" xyz="0 0 0"/>
      <geometry>
        <box size="0.015 0.015 0.004"/>
      </geometry>
    </visual>
    <material name="orange">
      <color rgba="255 108 10 255"/>
    </material>
  </link>
	  <gazebo reference="imu_joint">
    <disableFixedJointLumping>true</disableFixedJointLumping>
  </gazebo>




  <!-- ************************************************************ -->
  <!-- ************************ right Leg ************************** -->
  <!-- ************************************************************ -->

	<!-- yaw L2 -->
	<joint name="leg_r2_joint" type="revolute">
		<origin xyz="0 -0.075 0" rpy="3.1416 0 -1.5708" />
		<parent link="base_link" />
		<child link="leg_r2_link" />
		<axis xyz="0 0 -1" />
		<limit lower="-1" upper="0.5" effort="15" velocity="20" />
	</joint>
	<link name="leg_r2_link">
		<inertial>
			<origin xyz="6.4093E-09 0.056047 0.046574" rpy="0 0 0" />
			<mass value="0.34" />
			<inertia ixx="0.0003820" ixy="0.0000000" ixz="0.0000000"
									 iyy="0.0001983" iyz="0.0001824" 
									 				 izz="0.0001988" />
		</inertial>
		<visual>
			<origin xyz="0 0 0" rpy="0 0 0" />
			<geometry>
				<mesh filename="package://legged_hunter_description/meshes_pi/leg_r2_link.STL" />
			</geometry>
			<material name="">
				<color rgba="1 1 1 1" />
			</material>
		</visual>
		<collision>
			<!-- <origin xyz="0 0 0" rpy="0 0 0" />
			<geometry>
				<mesh filename="package://legged_hunter_description/meshes_pi/right_hip_yaw_link.STL" />
			</geometry> -->
			<origin xyz="0 0 0" rpy="0 0 0" />
			<geometry>
				<box size="0.0001 0.0001 0.0001" />
			</geometry>
		</collision>
	</link>
	

	<!-- roll L1 -->
	<joint name="leg_r1_joint" type="revolute">
		<origin xyz="0 0 0.054" rpy="1.5708 0 0" />
		<parent link="leg_r2_link" />
		<child link="leg_r1_link" />
		<axis xyz="0 0 1" />
		<limit lower="-0.5" upper="0.2" effort="15" velocity="20" />
	</joint>

	<link name="leg_r1_link">
		<inertial>
			<origin xyz="0.030907 0.00085876 -0.0037549" rpy="0 0 0" />
			<mass value="0.367" />
			<inertia ixx="0.0001795" ixy="0.0000000" ixz="0.0000000" 
									 iyy="0.0001796" iyz="-0.0000226" 
									                 izz="0.0000440" />
		</inertial>
		<visual>
			<origin xyz="0 0 0" rpy="0 0 0" />
			<geometry>
				<mesh filename="package://legged_hunter_description/meshes_pi/leg_r1_link.STL" />
			</geometry>
			<material name="">
				<color rgba="1 1 1 1" />
			</material>
		</visual>
		<collision>
			<!-- <origin xyz="0 0 0" rpy="0 0 0" />
			<geometry>
				<mesh filename="package://legged_hunter_description/meshes_pi/right_hip_roll_link.STL" />
			</geometry> -->
			<origin rpy="0 0 0" xyz="0 0 0" />
			<geometry>
				<box size="0.0001 0.0001 0.0001" />
			</geometry>
		</collision>
	</link>

	


	<!-- pitch l3 -->
	<joint name="leg_r3_joint" type="revolute">
		<origin xyz="0 0 0.002" rpy="-1.5708 0 1.5708" />
		<parent link="leg_r1_link" />
		<child link="leg_r3_link" />
		<axis xyz="0 0 1" />
		<limit lower="-1.2" upper="0.8" effort="15" velocity="21"  />
	</joint>
	<link name="leg_r3_link">
		<inertial>
			<origin xyz="0.022326 1.3878E-17 0.023954" rpy="0 0 0" />
			<mass value="0.476" />
			<inertia ixx="0.0000351" ixy="0.0000000" ixz="-0.0000193" 
									  iyy="0.0023912" iyz="0.0000000" 
									  				   izz="0.0023887" />
		</inertial>
		<visual>
			<origin xyz="0 0 0" rpy="0 0 0" />
			<geometry>
				<mesh filename="package://legged_hunter_description/meshes_pi/leg_r3_link.STL" />
			</geometry>
			<material name="">
				<color rgba="1 1 1 1" />
			</material>
		</visual>
		<collision>
			<!-- <origin xyz="0 0 0" rpy="0 0 0" />
			<geometry>
				<mesh filename="package://legged_hunter_description/meshes_pi/right_calf_link.STL" />
			</geometry> -->
			<origin xyz="0.05 0 0.0" rpy="0 1.57 0" />
            <geometry>
                <box size="0.01 0.01 0.09" />
            </geometry>
		</collision>
	</link>

	
	<!-- knee l4 -->
	<joint name="leg_r4_joint" type="revolute">
		<origin xyz="0.15 0 0" rpy="-3.1416 0 0" />
		<parent link="leg_r3_link" />
		<child link="leg_r4_link" />
		<axis xyz="0 0 -1" />
		<limit lower="0" upper="1.5" effort="15" velocity="20" />
	</joint>

	<link name="leg_r4_link">
		<inertial>
			<origin xyz="0.063722 -0.0045962 0.012568" rpy="0 0 0" />
			<mass value="0.361" />
			<inertia ixx="0.0001823" ixy="-0.0001000" ixz="0.0002734" 
									  iyy="0.0019799" iyz="-0.0000342" 
									  				  izz="0.0018988" />
		</inertial>
		<visual>
			<origin xyz="0 0 0" rpy="0 0 0" />
			<geometry>
				<mesh filename="package://legged_hunter_description/meshes_pi/leg_r4_link.STL" />
			</geometry>
			<material name="">
				<color rgba="1 1 1 1" />
			</material>
		</visual>
		<collision>
			<!-- <origin xyz="0 0 0" rpy="0 0 0" />
			<geometry>
				<mesh filename="package://legged_hunter_description/meshes_pi/right_thigh_Link.STL" />
			</geometry> -->
			<origin xyz="0.05 0.0 -0.0" rpy="0 1.57 0" />
			<geometry>
				<box size="0.01 0.01 0.09" />
			</geometry>
		</collision>
	</link>

	
	<!-- ankle L5 -->
	<joint name="leg_r5_joint" type="revolute">
		<origin xyz="0.16 0 0" rpy="3.1416 0 1.5708" />
		<parent link="leg_r4_link" />
		<child link="leg_r5_link" />
		<axis xyz="0 0 1" />
		<limit lower="-1.1" upper="1.1" effort="15" velocity="20" />
	</joint>
	<link name="leg_r5_link">
		<inertial>
			<origin xyz="0.0018242 0.014051 -1.6651E-08" rpy="0 0 0" />
			<mass value="0.089" />
			<inertia ixx="0.0000189" ixy="0.0000034" ixz="0.0000000" 
									 iyy="0.0000420" iyz="0.0000000" 
									  				  izz="0.0000580" />
		</inertial>
		<visual>

			<origin xyz="0.012 0.012 0.0" rpy="1.57 0 0" />
			<!-- <origin xyz="0.0 0.0 -0.02" rpy="0 1.57079 0" /> -->
            <geometry>
                <box size="0.1 0.04 0.01" />
				
				<!-- <mesh filename="package://legged_hunter_description/meshes_pi/leg_r5_link.STL" /> -->
				<!-- <cylinder length="0.1" radius="0.005"/> -->
            </geometry>
			<material name="">
				<color rgba="1 1 1 1" />
			</material>
		</visual>
		<collision>
			<origin xyz="0.012 0.012 0.0" rpy="1.57 0 0" />
			<!-- <origin xyz="0.0 0.0 -0.02" rpy="0 1.57079 0" /> -->
            <geometry>
                <box size="0.1 0.04 0.01" />
				<!-- <cylinder length="0.1" radius="0.005"/> -->
            </geometry>
		</collision>
	</link>

    <!-- ************* fixed *************** -->

	<joint name="leg_r5_fixed_1" type="fixed">
    <origin xyz="0.06 0 -0.007" rpy="0 0 0" />
    <parent link="leg_r5_link" />
    <child link="leg_r_f1_link" />
  </joint>
  <link name="leg_r_f1_link">
    <inertial>
      <mass value="0.01" />
      <inertia ixx="0.000001" ixy="0" ixz="0" iyy="0.000001" iyz="0" izz="0.000001" />
    </inertial>
    <visual>
      <origin rpy="0 0 0" xyz="0 0 0"/>
      <geometry>
        <sphere radius="0.001"/>
      </geometry>
    </visual>
    <collision>
      <origin rpy="0 0 0" xyz="0 0 0"/>
      <geometry>
        <sphere radius="0.001"/>
      </geometry>
    </collision>
  </link>

  <joint name="leg_r5_fixed_2" type="fixed">
    <origin xyz="-0.030 0 -0.007" rpy="0 0 0" />
    <parent link="leg_r5_link" />
    <child link="leg_r_f2_link" />
  </joint>
  <link name="leg_r_f2_link">
    <inertial>
      <mass value="0.01" />
      <inertia ixx="0.000001" ixy="0" ixz="0" iyy="0.000001" iyz="0" izz="0.000001" />
    </inertial>
    <visual>
      <origin rpy="0 0 0" xyz="0 0 0"/>
      <geometry>
        <sphere radius="0.001"/>
      </geometry>
    </visual>
    <collision>
      <origin rpy="0 0 0" xyz="0 0 0"/>
      <geometry>
        <sphere radius="0.001"/>
      </geometry>
    </collision>
  </link>
    <!-- ************* gazebo *************** -->

  <gazebo reference="leg_r2_link">
    <mu1>0.6</mu1>
    <mu2>0.6</mu2>
    <self_collide>1</self_collide>
  </gazebo>
  <gazebo reference="leg_r1_link">
    <mu1>0.6</mu1>
    <mu2>0.6</mu2>
    <self_collide>1</self_collide>
  </gazebo>
  <gazebo reference="leg_r3_link">
    <mu1>0.6</mu1>
    <mu2>0.6</mu2>
    <self_collide>1</self_collide>
  </gazebo>
  <gazebo reference="leg_r4_link">
    <mu1>0.6</mu1>
    <mu2>0.6</mu2>
    <self_collide>1</self_collide>
  </gazebo>
  <gazebo reference="leg_r5_link">
    <mu1>1.5</mu1>
    <mu2>1.5</mu2>
    <self_collide>1</self_collide>
    <kp value="1000000.0"/>
    <kd value="100.0"/>
    <maxVel>1.0</maxVel>
    <minDepth>0.00</minDepth>
  </gazebo>
  <gazebo reference="leg_r_f1_link">
    <mu1>1.5</mu1>
    <mu2>1.5</mu2>
    <self_collide>1</self_collide>
    <kp value="1000000.0"/>
    <kd value="100.0"/>
    <maxVel>1.0</maxVel>
    <minDepth>0.00</minDepth>
  </gazebo>
  <gazebo reference="leg_r_f2_link">
    <mu1>1.5</mu1>
    <mu2>1.5</mu2>
    <self_collide>1</self_collide>
    <kp value="1000000.0"/>
    <kd value="100.0"/>
    <maxVel>1.0</maxVel>
    <minDepth>0.00</minDepth>
  </gazebo>

    <!-- ************* transmission *************** -->


  <transmission name="leg_r1_tran">
    <type>transmission_interface/SimpleTransmission</type>
    <joint name="leg_r1_joint">
      <hardwareInterface>hardware_interface/EffortJointInterface</hardwareInterface>
    </joint>
    <actuator name="leg_r1_motor">
      <hardwareInterface>hardware_interface/EffortJointInterface</hardwareInterface>
      <mechanicalReduction>1</mechanicalReduction>
      	  <maxVelocity>1.484</maxVelocity><!-- 85rpm -->
	<maxEffort>36.0</maxEffort><!-- 36Nm -->
    </actuator>
  </transmission>

  <transmission name="leg_r2_tran">
    <type>transmission_interface/SimpleTransmission</type>
    <joint name="leg_r2_joint">
      <hardwareInterface>hardware_interface/EffortJointInterface</hardwareInterface>
    </joint>
    <actuator name="leg_r2_motor">
      <hardwareInterface>hardware_interface/EffortJointInterface</hardwareInterface>
      <mechanicalReduction>1</mechanicalReduction>
      	  <maxVelocity>2.6545</maxVelocity><!-- 160rpm -->
	  <maxEffort>94.0</maxEffort><!-- 94Nm -->
    </actuator>
  </transmission>

  <transmission name="leg_r3_tran">
    <type>transmission_interface/SimpleTransmission</type>
    <joint name="leg_r3_joint">
      <hardwareInterface>hardware_interface/EffortJointInterface</hardwareInterface>
    </joint>
    <actuator name="leg_r3_motor">
      <hardwareInterface>hardware_interface/EffortJointInterface</hardwareInterface>
      <mechanicalReduction>1</mechanicalReduction>
      	  <maxVelocity>2.6545</maxVelocity><!-- 160rpm -->
	  <maxEffort>94.0</maxEffort><!-- 94Nm -->
    </actuator>
  </transmission>

  <transmission name="leg_r4_tran">
    <type>transmission_interface/SimpleTransmission</type>
    <joint name="leg_r4_joint">
      <hardwareInterface>hardware_interface/EffortJointInterface</hardwareInterface>
    </joint>
    <actuator name="leg_r4_motor">
      <hardwareInterface>hardware_interface/EffortJointInterface</hardwareInterface>
      <mechanicalReduction>1</mechanicalReduction>
      	  <maxVelocity>1.484</maxVelocity><!-- 85rpm -->
	<maxEffort>36.0</maxEffort><!-- 36Nm -->
    </actuator>
  </transmission>

  <transmission name="leg_r5_tran">
    <type>transmission_interface/SimpleTransmission</type>
    <joint name="leg_r5_joint">
      <hardwareInterface>hardware_interface/EffortJointInterface</hardwareInterface>
    </joint>
    <actuator name="leg_r5_motor">
      <hardwareInterface>hardware_interface/EffortJointInterface</hardwareInterface>
      <mechanicalReduction>1</mechanicalReduction>
    </actuator>
  </transmission>


 <!-- ************************************************************ -->
  <!-- ************************ Left Leg ************************** -->
  <!-- ************************************************************ -->

  <!-- ************* part 1 *************** -->

	<joint name="leg_l2_joint" type="revolute">
		<origin xyz="0 0.075 0" rpy="-3.1416 0 -3.1416" />
		<parent link="base_link" />
		<child link="leg_l2_link" />
		<axis xyz="0 0 -1" />
		<limit lower="-0.5" upper="1" effort="15" velocity="20" />
	</joint>
  <link name="leg_l2_link">
		<inertial>
			<origin xyz="0.056047 -6.4093E-09 0.046574" rpy="0 0 0" />
			<mass value="0.34" />
			<inertia ixx="0.0001983" ixy="0.0000000" ixz="0.0001824" 
									 iyy="0.0003820"  iyz="0.0000000" 
									 				   izz="0.0001988" />
		</inertial>
		<visual>
			<origin xyz="0 0 0" rpy="0 0 0" />
			<geometry>
				<mesh filename="package://legged_hunter_description/meshes_pi/leg_l2_link.STL" />
			</geometry>
			<material name="">
				<color rgba="1 1 1 1" />
			</material>
		</visual>
		<collision>
			<!-- <origin xyz="0 0 0" rpy="0 0 0" />
			<geometry>
				<mesh filename="package://legged_hunter_description/meshes_pi/leg_l2_link.STL" />
			</geometry> -->
			<origin xyz="0 0 0" rpy="0 0 0" />
			<geometry>
				<box size="0.0001 0.0001 0.0001" />
			</geometry>
		</collision>
	</link>

  <!-- ************* part 2 *************** -->

  <joint name="leg_l1_joint" type="revolute">
		<origin xyz="0 0 0.054" rpy="-1.5708 0 1.5708" />
		<parent link="leg_l2_link" />
		<child link="leg_l1_link" />
		<axis xyz="0 0 1" />
		<limit lower="-0.2" upper="0.5" effort="15" velocity="20" />
	</joint>

	<link name="leg_l1_link">
		<inertial>
			<origin xyz="0.030907 -0.00085876 -0.0037549" rpy="0 0 0" />
			<mass value="0.12545" />
			<inertia ixx="0.0001795" ixy="0.0000000" ixz="0.0000000" 
			                         iyy="0.0001796" iyz="0.0000226" 
									                 izz="0.0000440" />
		</inertial>
		<visual>
			<origin xyz="0 0 0" rpy="0 0 0" />
			<geometry>
				<mesh filename="package://legged_hunter_description/meshes_pi/leg_l1_link.STL" />
			</geometry>
			<material name="">
				<color rgba="1 1 1 1" />
			</material>
		</visual>
		<collision>
			<!-- <origin xyz="0 0 0" rpy="0 0 0" />
			<geometry>
				<mesh filename="package://legged_hunter_description/meshes_pi/leg_l1_link.STL" />
			</geometry> -->
			<origin rpy="0 0 0" xyz="0 0 0" />
			<geometry>
				<box size="0.0001 0.0001 0.0001" />
			</geometry>
		</collision>
	</link>

  <!-- ************* part 3 *************** -->

	<joint name="leg_l3_joint" type="revolute">
		<origin xyz="0 0 0.002" rpy="1.5708 0 -1.5708" />
		<parent link="leg_l1_link" />
		<child link="leg_l3_link" />
		<axis xyz="0 0 1" />
		<limit lower="-0.8" upper="1.2" effort="15" velocity="20" />
	</joint>

	<link name="leg_l3_link">
		<inertial>
			<origin xyz="0.022326 0 0.023954" rpy="0 0 0" />
			<mass value="0.476" />
			<inertia ixx="0.0000351" ixy="0.0000000" ixz="-0.0000193" 
									 iyy="0.0023912" iyz="0.0000000" 
									 				 izz="0.0023887" />
		</inertial>
		<visual>
			<origin xyz="0 0 0" rpy="0 0 0" />
			<geometry>
				<mesh filename="package://legged_hunter_description/meshes_pi/leg_l3_link.STL" />
			</geometry>
			<material name="">
				<color rgba="1 1 1 1" />
			</material>
		</visual>
		<collision>
			<!-- <origin xyz="0 0 0" rpy="0 0 0" />
			<geometry>
				<mesh filename="package://legged_hunter_description/meshes_pi/leg_l3_link.STL" />
			</geometry> -->
			<origin xyz="0.05 0 0.0" rpy="0 1.57 0" />
			<geometry>
				<box size="0.01 0.01 0.09" />
			</geometry>
		</collision>
	</link>

   <!-- ************* part 4 *************** -->
  <joint name="leg_l4_joint" type="revolute">
		<origin xyz="0.15 0 0" rpy="3.1416 0 0" />
		<parent link="leg_l3_link" />
		<child link="leg_l4_link" />
		<axis xyz="0 0 1" />
		<limit lower="0" upper="1.5" effort="15" velocity="20" />
	</joint>
	<link name="leg_l4_link">
		<inertial>
			<origin xyz="0.063722 0.0045962 0.012568" rpy="0 0 0" />
			<mass value="0.361" />
			<inertia ixx="0.0001823" ixy="0.0001000" ixz="0.0002734" 
									 iyy="0.0019799" iyz="0.0000342" 
									 				 izz="0.0018988" />
		</inertial>
		<visual>
			<origin xyz="0 0 0" rpy="0 0 0" />
			<geometry>
				<mesh filename="package://legged_hunter_description/meshes_pi/leg_l4_link.STL" />
			</geometry>
			<material name="">
				<color rgba="1 1 1 1" />
			</material>
		</visual>
		<collision>
			<origin xyz="0.05 0.0 0.0" rpy="0 1.57 0" />
			<geometry>
				<box size="0.01 0.01 0.09" />
			</geometry>
		</collision>
	</link>
	
    <!-- ************* part 5 *************** -->
  <joint name="leg_l5_joint" type="revolute">
		<origin xyz="0.16 0 0" rpy="3.1416 0 -1.5708" />
		<parent link="leg_l4_link" />
		<child link="leg_l5_link" />
		<axis xyz="0 0 1" />
		<limit lower="-1.1" upper="1.1" effort="15" velocity="20" />
	</joint>

	<link name="leg_l5_link">
		<inertial>
			<origin xyz="0.0018242 -0.014051 1.6804E-08" rpy="1.57 0 0" />
			<mass value="0.089" />
			<inertia ixx="0.0000189" ixy="-0.0000034" ixz="0.0000000" 
								     iyy="0.0000420" iyz="0.0000000" 
									 				  izz="0.0000580" />
		</inertial>
		<visual>
			<origin xyz="0.012 -0.012 0.0" rpy="1.57 0 0" />
			<geometry>
				<box size="0.1 0.04 0.01" />
			</geometry>
			<material name="">
				<color rgba="1 1 1 1" />
			</material>
		</visual>
		<collision>
			<origin xyz="0.012 -0.012 0.0" rpy="1.57 0.0 0" />
			<geometry>
				<box size="0.1 0.04 0.01" />
				<!-- <cylinder length="0.1" radius="0.005"/> -->
			</geometry>
		</collision>
	</link>

    <!-- ************* fixed *************** -->

  <joint name="leg_l5_fixed_1" type="fixed">
    <origin xyz="0.06 0 -0.007" rpy="0 0 0" />
    <parent link="leg_l5_link" />
    <child link="leg_l_f1_link" />
  </joint>
  <link name="leg_l_f1_link">
    <inertial>
      <mass value="0.01" />
      <inertia ixx="0.000001" ixy="0" ixz="0" iyy="0.000001" iyz="0" izz="0.000001" />
    </inertial>
    <visual>
      <origin rpy="0 0 0" xyz="0 0 0"/>
      <geometry>
        <sphere radius="0.001"/>
      </geometry>
    </visual>
    <collision>
      <origin rpy="0 0 0" xyz="0 0 0"/>
      <geometry>
        <sphere radius="0.001"/>
      </geometry>
    </collision>
  </link>

  <joint name="leg_l5_fixed_2" type="fixed">
    <origin xyz="-0.030 0 -0.007" rpy="0 0 0" />
    <parent link="leg_l5_link" />
    <child link="leg_l_f2_link" />
  </joint>
  <link name="leg_l_f2_link">
    <inertial>
      <mass value="0.01" />
      <inertia ixx="0.000001" ixy="0" ixz="0" iyy="0.000001" iyz="0" izz="0.000001" />
    </inertial>
    <visual>
      <origin rpy="0 0 0" xyz="0 0 0"/>
      <geometry>
        <sphere radius="0.001"/>
      </geometry>
    </visual>
    <collision>
      <origin rpy="0 0 0" xyz="-0 0 0"/>
      <geometry>
        <sphere radius="0.001"/>
      </geometry>
    </collision>
  </link>

    <!-- ************* gazebo *************** -->

  <gazebo reference="leg_l1_link">
    <mu1>0.6</mu1>
    <mu2>0.6</mu2>
    <self_collide>1</self_collide>
  </gazebo>
  <gazebo reference="leg_l2_link">
    <mu1>0.6</mu1>
    <mu2>0.6</mu2>
    <self_collide>1</self_collide>
  </gazebo>
  <gazebo reference="leg_l3_link">
    <mu1>0.6</mu1>
    <mu2>0.6</mu2>
    <self_collide>1</self_collide>
  </gazebo>
  <gazebo reference="leg_l4_link">
    <mu1>0.6</mu1>
    <mu2>0.6</mu2>
    <self_collide>1</self_collide>
  </gazebo>
  <gazebo reference="leg_l5_link">
    <mu1>1.5</mu1>
    <mu2>1.5</mu2>
    <self_collide>1</self_collide>
    <kp value="1000000.0"/>
    <kd value="100.0"/>
    <maxVel>1.0</maxVel>
    <minDepth>0.00</minDepth>
  </gazebo>
  <gazebo reference="leg_l_f1_link">
    <mu1>1.5</mu1>
    <mu2>1.5</mu2>
    <self_collide>1</self_collide>
    <kp value="1000000.0"/>
    <kd value="100.0"/>
    <maxVel>1.0</maxVel>
    <minDepth>0.00</minDepth>
  </gazebo>
  <gazebo reference="leg_l_f2_link">
    <mu1>1.5</mu1>
    <mu2>1.5</mu2>
    <self_collide>1</self_collide>
    <kp value="1000000.0"/>
    <kd value="100.0"/>
    <maxVel>1.0</maxVel>
    <minDepth>0.00</minDepth>
  </gazebo>

    <!-- ************* transmission *************** -->

  <transmission name="leg_l1_tran">
    <type>transmission_interface/SimpleTransmission</type>
    <joint name="leg_l1_joint">
      <hardwareInterface>hardware_interface/EffortJointInterface</hardwareInterface>
    </joint>
    <actuator name="leg_l1_motor">
      <hardwareInterface>hardware_interface/EffortJointInterface</hardwareInterface>
      <mechanicalReduction>1</mechanicalReduction>
    <maxVelocity>1.484</maxVelocity><!-- 85rpm -->
	  <maxEffort>36.0</maxEffort><!-- 36Nm -->
    </actuator>
  </transmission>

  <transmission name="leg_l2_tran">
    <type>transmission_interface/SimpleTransmission</type>
    <joint name="leg_l2_joint">
      <hardwareInterface>hardware_interface/EffortJointInterface</hardwareInterface>
    </joint>
    <actuator name="leg_l2_motor">
      <hardwareInterface>hardware_interface/EffortJointInterface</hardwareInterface>
      <mechanicalReduction>1</mechanicalReduction>
    <maxVelocity>2.6545</maxVelocity><!-- 160rpm -->
	  <maxEffort>94.0</maxEffort><!-- 94Nm -->
    </actuator>
  </transmission>

  <transmission name="leg_l3_tran">
    <type>transmission_interface/SimpleTransmission</type>
    <joint name="leg_l3_joint">
      <hardwareInterface>hardware_interface/EffortJointInterface</hardwareInterface>
    </joint>
    <actuator name="leg_l3_motor">
      <hardwareInterface>hardware_interface/EffortJointInterface</hardwareInterface>
      <mechanicalReduction>1</mechanicalReduction>
    <maxVelocity>2.6545</maxVelocity><!-- 160rpm -->
	  <maxEffort>94.0</maxEffort><!-- 94Nm -->
    </actuator>
  </transmission>

  <transmission name="leg_l4_tran">
    <type>transmission_interface/SimpleTransmission</type>
    <joint name="leg_l4_joint">
      <hardwareInterface>hardware_interface/EffortJointInterface</hardwareInterface>
    </joint>
    <actuator name="leg_l4_motor">
      <hardwareInterface>hardware_interface/EffortJointInterface</hardwareInterface>
      <mechanicalReduction>1</mechanicalReduction>
    <maxVelocity>1.484</maxVelocity><!-- 85rpm -->
	<maxEffort>36.0</maxEffort><!-- 36Nm -->
    </actuator>
  </transmission>

  <transmission name="leg_l5_tran">
    <type>transmission_interface/SimpleTransmission</type>
    <joint name="leg_l5_joint">
      <hardwareInterface>hardware_interface/EffortJointInterface</hardwareInterface>
    </joint>
    <actuator name="leg_l5_motor">
      <hardwareInterface>hardware_interface/EffortJointInterface</hardwareInterface>
      <mechanicalReduction>1</mechanicalReduction>
    </actuator>
  </transmission>
</robot>
